Workbook

Sheet PROGRAMACION SERVICIO AGUAS
A1: EMPRESA AGUAS DE FACATATIVÁ, Acueducto, Alcantarillado, Aseo y Servicios Complementarios EAF SAS ESP | E1: TRAZABILIDAD A MUESTRAS DE AGUA QUE INGRESAN AL LABORATORIO PROCESO ACUEDUCTO INSTRUCTIVO – TOMA, MANIPULACIÓN, TRANSPORTE, PRESERVACIÓN, CONSERVACIÓN Y DISPOSICIÓN FINAL DE ÍTEMS DE ENSAYO | T1: Código: Ft 004-06-1604
T2: Versión No: 04
T3: Fecha de implementación: 2022-11-04
T5: No. Páginas: 1
A8: FECHA DEL MUESTREO | D8: 45323
A10: INFORMACIÓN DE LA TOMA DE LA MUESTRA | N10: INFORMACIÓN DE LA RECEPCIÓN DE LA MUESTRA | R10: INFORMACIÓN DEL ANÁLISIS DE LA MUESTRA | V10: ELIMINACIÓN
A11: CODIFICACIÓN ÍTEM DE ENSAYO | B11: HORA DEL MUESTREO | C11: TIPO DE AGUA* | D11: FUENTE DE ABASTECIMIENTO | E11: PUNTO DE TOMA - CÓDIGO (SI APLICA) | F11: DISPOSITIVO DE TOMA | G11: ANÁLISIS A REALIZAR | J11: RESULTADOS ANÁLISIS "IN SITU" | M11: MUESTREA | N11: FECHA DE RECEPCIÓN | O11: HORA DE RECEPCIÓN | P11: TEMPERATURA DE RECEPCIÓN | Q11: RECEPCIONA | R11: FECHA DE ANÁLISIS | S11: HORA DE INICIO DE ANÁLISIS | T11: TEMPERATURA DE ANÁLISIS | U11: ANALIZA | V11: FECHA DE ELIMINACIÓN | W11: OBSERVACIÓN
G12: FQ | H12: MB | J12: Cl2 | K12: pH | L12: °C
H13: 1 | I13: 2
A14: I24-083 | B14: 8 h 20 min | C14: AP | D14: Planta | E14: - | F14: Manguera | G14: X | H14: X | I14: - | J14: 1.65 | K14: 7.28 | L14: 18.9 | M14: Gloria Triana | N14: =+$D$8 -> 45323 | O14: 8 h 30 min | P14: 18.9 | Q14: Lina Vasquez | R14: =+N14 -> 45323 | S14: 8 h 35 min | T14: =+Resultados!F16 -> 18.8 | U14: Lina Vasquez | V14: =+R14+1 -> 45324 | W14: -
A15: I24-084 | B15: 8 h 25 min | C15: ASP | D15: Embalse | E15: - | F15: Canal | G15: X | I15: - | J15: - | K15: 6.98 | L15: 18.7 | M15: Gloria Triana | N15: =+$D$8 -> 45323 | O15: 8 h 30 min | P15: 18.7 | Q15: Lina Vasquez | R15: =+N15 -> 45323 | S15: 8 h 35 min | T15: =+Resultados!H16 -> 18.5 | U15: Lina Vasquez | V15: =+R15+1 -> 45324 | W15: -
A16: R24-02-001 | B16: 8 h 35 min | C16: AP | D16: Red | E16: 6 | F16: Grifo | G16: X | H16: X | I16: - | J16: 1 | K16: 7.6 | L16: 18.6 | M16: Gloria Triana | N16: =+$D$8 -> 45323 | O16: 9 h 40 min | P16: 18.9 | Q16: Lina Vasquez | R16: =+N16 -> 45323 | S16: 10 h | T16: =+Resultados!J16 -> 18 | U16: Lina Vasquez | V16: =+R16+1 -> 45324 | W16: -
A17: R24-02-002 | B17: 14 h 15 min | C17: AP | D17: Red | E17: 16 | F17: Grifo | G17: X | H17: X | I17: - | J17: 0 | K17: 7.47 | L17: 19.8 | M17: Gloria Triana | N17: =+$D$8 -> 45323 | O17: 15 h 05 min | P17: 22.2 | Q17: Lina Vasquez | R17: =+N17 -> 45323 | S17: 15 h 10 min | T17: =+Resultados!L16 -> 20.9 | U17: Lina Vasquez | V17: =+R17+1 -> 45324 | W17: -
A18: R24-02-003 | B18: 14 h 30 min | C18: AP | D18: Red | E18: 10 | F18: Grifo | G18: X | H18: X | I18: - | J18: 0.8 | K18: 7.61 | L18: 18.2 | M18: Gloria Triana | N18: =+$D$8 -> 45323 | O18: 15 h 05 min | P18: 20.9 | Q18: Lina Vasquez | R18: =+N18 -> 45323 | S18: 15 h 10 min | T18: =+Resultados!N16 -> 19.7 | U18: Lina Vasquez | V18: =+R18+1 -> 45324 | W18: -
A19: R24-02-004 | B19: 14 h 50 min | C19: AP | D19: Red | E19: 4 | F19: Grifo | G19: X | H19: X | I19: - | J19: 1 | K19: 7.65 | L19: 20.2 | M19: Gloria Triana | N19: =+$D$8 -> 45323 | O19: 15 h 05 min | P19: 22.9 | Q19: Lina Vasquez | R19: =+N19 -> 45323 | S19: 15 h 10 min | T19: =+Resultados!P16 -> 21.2 | U19: Lina Vasquez | V19: =+R19+1 -> 45324 | W19: -
A20: - | B20: - | C20: - | D20: - | E20: - | F20: - | G20: - | H20: - | I20: - | J20: - | K20: - | L20: - | M20: - | N20: - | O20: - | P20: - | Q20: - | R20: - | S20: - | T20: - | U20: - | V20: - | W20: -
A21: - | B21: - | C21: - | D21: - | E21: - | F21: - | G21: - | H21: - | I21: - | J21: - | K21: - | L21: - | M21: - | N21: - | O21: - | P21: - | Q21: - | R21: - | S21: - | T21: - | U21: - | V21: - | W21: -
A22: - | B22: - | C22: - | D22: - | E22: - | F22: - | G22: - | H22: - | I22: - | J22: - | K22: - | L22: - | M22: - | N22: - | O22: - | P22: - | Q22: - | R22: - | S22: - | T22: - | U22: - | V22: - | W22: -
A23: OBSERVACIONES GENERALES:
A24: Ninguna
A26: EQUIPOS Y MÉTODOS DE ANÁLISIS "IN SITU" PARA MUESTRAS DE CODIFICACIÓN RED Y/O INTERNAS:
A27: Cloro residual libre | C27: EQUIPO | F27: MÉTODO | K27: pH | M27: EQUIPO | O27: MÉTODO | R27: Temperatura | S27: EQUIPO | V27: MÉTODO
C28: COLORÍMETRO DE BOLSILLO | F28: COLORIMÉTRICO | M28: PH METRO | O28: ELECTROMÉTRICO | S28: PH METRO | U28: ELECTROMÉTRICO
A29: * Convenciones: Agua potable (AP) - Agua superficial (ASP) - Agua subterránea (ASB) - Agua envasada (AE) - Agua lluvia (AL) - Otra (O)

Sheet Resultados
A1: EMPRESA AGUAS DE FACATATIVÁ, Acueducto, Alcantarillado, Aseo y Servicios Complementarios EAF SAS ESP | E1: RESULTADOS DE ENSAYO – LABORATORIO DE AGUAS PROCESO ACUEDUCTO INSTRUCTIVO – CONTROL DE LOS DATOS – LABORATORIO DE AGUAS | S1: Código: Ft 004-06-1801
S2: Versión: 05
S3: Fecha de implementación: 2021-08-11
S4: N° de páginas: 1 de 2
A6: INFORMACIÓN DE LA MUESTRA
A7: FECHA DE MUESTREO | E7: =E14:F14 -> 45323
A8: TIPO DE AGUA | E8: =+'PROGRAMACION SERVICIO AGUAS'!$C14 -> AP | G8: =+'PROGRAMACION SERVICIO AGUAS'!$C15 -> ASP | I8: =+'PROGRAMACION SERVICIO AGUAS'!$C16 -> AP | K8: =+'PROGRAMACION SERVICIO AGUAS'!$C17 -> AP | M8: =+'PROGRAMACION SERVICIO AGUAS'!$C18 -> AP | O8: =+'PROGRAMACION SERVICIO AGUAS'!$C19 -> AP | Q8: =+'PROGRAMACION SERVICIO AGUAS'!$C20 -> - | S8: =+'PROGRAMACION SERVICIO AGUAS'!$C21 -> - | U8: =+'PROGRAMACION SERVICIO AGUAS'!$C22 -> -
A9: RESULTADOS ANÁLISIS "IN SITU" | D9: pH | E9: =+'PROGRAMACION SERVICIO AGUAS'!$K14 -> 7.28 | G9: =+'PROGRAMACION SERVICIO AGUAS'!$K15 -> 6.98 | I9: =+'PROGRAMACION SERVICIO AGUAS'!$K16 -> 7.6 | K9: =+'PROGRAMACION SERVICIO AGUAS'!$K17 -> 7.47 | M9: =+'PROGRAMACION SERVICIO AGUAS'!$K18 -> 7.61 | O9: =+'PROGRAMACION SERVICIO AGUAS'!$K19 -> 7.65 | Q9: =+'PROGRAMACION SERVICIO AGUAS'!$K20 -> - | S9: =+'PROGRAMACION SERVICIO AGUAS'!$K21 -> - | U9: =+'PROGRAMACION SERVICIO AGUAS'!$K22 -> -
D10: mg Cl2/L | E10: =+'PROGRAMACION SERVICIO AGUAS'!J14 -> 1.65 | G10: =+'PROGRAMACION SERVICIO AGUAS'!J15 -> - | I10: =+'PROGRAMACION SERVICIO AGUAS'!J16 -> 1 | K10: =+'PROGRAMACION SERVICIO AGUAS'!J17 -> 0 | M10: =+'PROGRAMACION SERVICIO AGUAS'!J18 -> 0.8 | O10: =+'PROGRAMACION SERVICIO AGUAS'!J19 -> 1 | Q10: =+'PROGRAMACION SERVICIO AGUAS'!J20 -> - | S10: =+'PROGRAMACION SERVICIO AGUAS'!J21 -> - | U10: =+'PROGRAMACION SERVICIO AGUAS'!J22 -> -
A11: OBSERVACIONES | E11: =+'PROGRAMACION SERVICIO AGUAS'!$W14 -> - | G11: =+'PROGRAMACION SERVICIO AGUAS'!$W15 -> - | I11: =+'PROGRAMACION SERVICIO AGUAS'!$W16 -> - | K11: =+'PROGRAMACION SERVICIO AGUAS'!$W17 -> - | M11: =+'PROGRAMACION SERVICIO AGUAS'!$W18 -> - | O11: =+'PROGRAMACION SERVICIO AGUAS'!$W19 -> - | Q11: =+'PROGRAMACION SERVICIO AGUAS'!$W20 -> - | S11: =+'PROGRAMACION SERVICIO AGUAS'!$W21 -> - | U11: =+'PROGRAMACION SERVICIO AGUAS'!$W22 -> -
A12: RESULTADOS DE ENSAYO - FISICOS Y QUÍMICOS
A13: CODIFICACIÓN | E13: =+'PROGRAMACION SERVICIO AGUAS'!$A14 -> I24-083 | G13: =+'PROGRAMACION SERVICIO AGUAS'!$A15 -> I24-084 | I13: =+'PROGRAMACION SERVICIO AGUAS'!$A16 -> R24-02-001 | K13: =+'PROGRAMACION SERVICIO AGUAS'!$A17 -> R24-02-002 | M13: =+'PROGRAMACION SERVICIO AGUAS'!$A18 -> R24-02-003 | O13: =+'PROGRAMACION SERVICIO AGUAS'!$A19 -> R24-02-004 | Q13: =+'PROGRAMACION SERVICIO AGUAS'!$A20 -> - | S13: =+'PROGRAMACION SERVICIO AGUAS'!$A21 -> - | U13: =+'PROGRAMACION SERVICIO AGUAS'!$A22 -> -
A14: FECHA DE ANÁLISIS | E14: =+'PROGRAMACION SERVICIO AGUAS'!R14 -> 45323 | G14: =+'PROGRAMACION SERVICIO AGUAS'!$R15 -> 45323 | I14: =+'PROGRAMACION SERVICIO AGUAS'!$R16 -> 45323 | K14: =+'PROGRAMACION SERVICIO AGUAS'!$R17 -> 45323 | M14: =+'PROGRAMACION SERVICIO AGUAS'!$R18 -> 45323 | O14: =+'PROGRAMACION SERVICIO AGUAS'!$R19 -> 45323 | Q14: =+'PROGRAMACION SERVICIO AGUAS'!$R20 -> - | S14: =+'PROGRAMACION SERVICIO AGUAS'!$R21 -> - | U14: =+'PROGRAMACION SERVICIO AGUAS'!$R22 -> -
A15: ENSAYO | C15: UNIDADES
A16: Temperatura | C16: °C | E16: X | F16: 18.8 | G16: X | H16: 18.5 | I16: X | J16: 18 | K16: X | L16: 20.9 | M16: X | N16: 19.7 | O16: X | P16: 21.2 | R16: - | T16: - | V16: -
A17: pH | C17: Unidades | E17: X | F17: =+E9 -> 7.28 | G17: X | H17: =+G9 -> 6.98 | I17: X | J17: =+I9 -> 7.6 | K17: X | L17: =+K9 -> 7.47 | M17: X | N17: =+M9 -> 7.61 | O17: X | P17: =+O9 -> 7.65 | R17: =+Q9 -> - | T17: =+S9 -> - | V17: =+U9 -> -
A18: Cloro residual libre | C18: mg Cl2/L | E18: X | F18: =+E10 -> 1.65 | H18: =+G10 -> - | I18: X | J18: =+I10 -> 1 | K18: X | L18: =+K10 -> 0 | M18: X | N18: =+M10 -> 0.8 | O18: X | P18: =+O10 -> 1 | R18: =+Q10 -> - | T18: =+S10 -> - | V18: =+U10 -> -
A19: Alcalinidad total | C19: mg CaCO3/L | E19: X | F19: 50 | G19: X | H19: 47.1 | I19: X | J19: 48.3 | L19: - | M19: X | N19: 42.2 | P19: - | R19: - | T19: - | V19: -
A20: Aluminio residual | C20: mg Al/L | F20: - | H20: - | J20: - | K20: X | L20: 0.03 | N20: - | O20: X | P20: - | R20: - | T20: - | V20: -
A21: Calcio | C21: mg Ca/L | F21: - | H21: - | J21: - | K21: X | L21: {=+(14.58*4.0078)} -> 58.433724 | N21: - | O21: X | P21: {=+(4.71*4.0078)} -> 18.876738 | R21: - | T21: - | V21: -
A22: Cloruros | C22: mg Cl-/L | F22: - | H22: - | I22: X | J22: {=+(4.24-1.9)*4.8921} -> 11.447514 | L22: - | M22: X | N22: {=+(2.94-1.9)*4.8921} -> 5.087784 | P22: - | R22: - | T22: - | V22: -
A23: Color aparente | C23: UPC | E23: X | F23: 7.8 | G23: X | H23: 21.5 | I23: X | J23: 7.5 | K23: X | L23: 4.2 | M23: X | N23: 2.1 | O23: X | P23: 9.3 | R23: - | T23: - | V23: -
A24: Conductividad | C24: µs/cm | E24: X | F24: 130.8 | G24: X | H24: 108.5 | I24: X | J24: 122.6 | K24: X | L24: 329 | M24: X | N24: 114.9 | O24: X | P24: 140 | R24: - | T24: - | V24: -
A25: Dureza total | C25: mg CaCO3/L | E25: X | F25: 59.5 | G25: X | H25: 46.4 | J25: - | K25: X | L25: 160.5 | N25: - | O25: X | P25: 56.7 | R25: - | T25: - | V25: -
A26: Fosfato | C26: mg PO43-/L | F26: - | H26: - | I26: X | J26: 0.05 | L26: - | M26: X | N26: 0.03 | P26: - | R26: - | T26: - | V26: -
A27: Hierro total | C27: mg Fe/L | E27: X | F27: 0.25 | G27: X | H27: 0.85 | J27: - | K27: X | L27: 0.29 | N27: - | O27: X | P27: 0.34 | R27: - | T27: - | V27: -
A28: Magnesio | C28: mg Mg/L | F28: - | H28: - | J28: - | K28: X | L28: =+(L25-(L21/4.0078)*10)*0.243 -> 3.5721 | N28: - | O28: X | P28: =+(P25-(P21/4.0078)*10)*0.243 -> 2.3328 | R28: - | T28: - | V28: -
A29: Nitrito | C29: mg NO2-/L | F29: - | H29: - | I29: X | J29: 0.021 | L29: - | M29: X | N29: 0.051 | P29: - | R29: - | T29: - | V29: -
A30: Sólidos disueltos totales | C30: mg/L | F30: - | H30: - | J30: - | L30: - | N30: - | P30: - | R30: - | T30: - | V30: -
A31: Sulfatos | C31: mg SO24-/L | F31: - | H31: - | I31: X | J31: {=((39.5+14.125)/4.2479)} -> 12.623885 | L31: - | M31: X | N31: {=((57.9+14.125)/4.2479)} -> 16.955437 | P31: - | R31: - | T31: - | V31: -
A32: Turbiedad | C32: UNT | E32: X | F32: 1.02 | G32: X | H32: 3.73 | I32: X | J32: 1.1 | K32: X | L32: 1.2 | M32: X | N32: 0.517 | O32: X | P32: 1.4 | R32: - | T32: - | V32: -
A33: ANOTACIONES | E33: - | G33: - | I33: - | K33: - | M33: - | O33: - | Q33: - | S33: - | U33: -
A34: EMPRESA AGUAS DE FACATATIVÁ, Acueducto, Alcantarillado, Aseo y Servicios Complementarios EAF SAS ESP | E34: RESULTADOS DE ENSAYO – LABORATORIO DE AGUAS PROCESO ACUEDUCTO INSTRUCTIVO – CONTROL DE LOS DATOS – LABORATORIO DE AGUAS | S34: Código: Ft 004-06-1801
S35: Versión: 05
S36: Fecha de implementación: 2021-08-11
S37: N° de páginas: 2 de 2
A39: CODIFICACIÓN | E39: - | G39: - | I39: - | K39: - | M39: - | O39: - | Q39: - | S39: - | U39: -
A40: FECHA DE ANÁLISIS | E40: - | G40: - | I40: - | K40: - | M40: - | O40: - | Q40: - | S40: - | U40: -
A41: ENSAYO | C41: UNIDADES
A42: Amonio | C42: mg NH4+/L | F42: - | H42: - | J42: - | L42: - | N42: - | P42: - | R42: - | T42: - | V42: -
...
